<mujoco model="panda scene">
  <compiler angle="radian" />

  <option timestep="0.005" integrator="implicitfast" iterations="5" ls_iterations="8">
    <flag eulerdamp="disable"/>
  </option>

  <size nkey="3"/>

  <visual>
    <global azimuth="120" elevation="-20"/>
    <headlight ambient="0.3 0.3 0.3" diffuse="0.6 0.6 0.6" specular="0 0 0"/>
    <scale forcewidth="0.05" contactwidth="0.075" contactheight="0.025" com="0.05" framelength="0.2" framewidth="0.01"/>
    <rgba haze="0.15 0.25 0.35 1"/>
  </visual>

  <statistic extent="1" center="0.3 0 0.4"/>

  <default>
    <default class="panda">
      <material shininess="0.25"/>
      <joint range="-2.8973 2.8973" armature="0.1" damping="1"/>
      <general ctrlrange="-2.8973 2.8973" forcerange="-100 100" biastype="affine" biasprm="0 -1"/>
      <default class="finger">
        <joint type="slide" range="0 0.04"/>
      </default>
      <default class="visual">
        <geom type="mesh" contype="0" conaffinity="0" group="2"/>
      </default>
      <default class="collision">
        <geom type="mesh" contype="0" conaffinity="0" group="3"/>
        <default class="primitive_collision">
          <geom type="box" solref="0.01" solimp="0.99 0.995 0.01"/>
          <default class="fingertip_pad_collision_1">
            <geom size="0.011 0.0075 0.01"/>
          </default>
          <default class="fingertip_pad_collision_2">
            <geom size="0.011 0.0044 0.0019"/>
          </default>
          <default class="fingertip_pad_collision_3">
            <geom size="0.00875 0.0035 0.01175"/>
          </default>
          <default class="fingertip_pad_collision_4">
            <geom size="0.00875 0.0076 0.00825" conaffinity="3"/>
          </default>
        </default>
      </default>
    </default>
  </default>

  <custom>
    <numeric name="max_contact_points" size="1" data="12"/>
  </custom>

  <asset>
    <texture type="skybox" builtin="gradient" rgb1="0.3 0.5 0.7" rgb2="0 0 0" width="512" height="3072"/>
    <texture type="2d" name="groundplane" builtin="checker" mark="edge" rgb1="0.2 0.3 0.4" rgb2="0.1 0.2 0.3" markrgb="0.8 0.8 0.8" width="300" height="300"/>
    <material name="white" class="panda"/>
    <material name="off_white" class="panda" rgba="0.901961 0.921569 0.929412 1"/>
    <material name="black" class="panda" rgba="0.25 0.25 0.25 1"/>
    <material name="green" class="panda" rgba="0 1 0 1"/>
    <material name="light_blue" class="panda" rgba="0.039216 0.541176 0.780392 1"/>
    <material name="groundplane" texture="groundplane" texuniform="true" texrepeat="5 5" reflectance="0.2"/>
  </asset>

  <worldbody>
    <geom name="floor" size="0 0 0.05" type="plane" material="groundplane"/>
    <light name="top" pos="0 0 2" dir="0 0 -1" mode="trackcom"/>
    <light pos="0 0 1.5" dir="0 0 -1" directional="true"/>
    <body name="link0" childclass="panda">
      <inertial pos="-0.041018 -0.00014 0.049974" quat="0.00630474 0.751245 0.00741774 0.659952" mass="0.629769" diaginertia="0.00430465 0.00387984 0.00313051"/>
      <body name="link1" pos="0 0 0.333">
        <inertial pos="0.003875 0.002081 -0.04762" quat="0.711549 0.00634377 -0.0131124 0.702485" mass="4.97068" diaginertia="0.707137 0.703435 0.00852456"/>
        <joint name="joint1" pos="0 0 0" axis="0 0 1" damping="40"/>
        <body name="link2" quat="0.707107 -0.707107 0 0">
          <inertial pos="-0.003141 -0.02872 0.003495" quat="-0.168175 0.828366 -0.122878 0.520027" mass="0.646926" diaginertia="0.0310326 0.0283001 0.00273425"/>
          <joint name="joint2" pos="0 0 0" axis="0 0 1" range="-1.7628 1.7628" damping="40"/>
          <body name="link3" pos="0 -0.316 0" quat="0.707107 0.707107 0 0">
            <inertial pos="0.027518 0.039252 -0.066502" quat="0.662769 -0.00678331 0.252053 0.705096" mass="3.2286" diaginertia="0.0415014 0.0414793 0.00124635"/>
            <joint name="joint3" pos="0 0 0" axis="0 0 1" damping="40"/>
            <body name="link4" pos="0.0825 0 0" quat="0.707107 0.707107 0 0">
              <inertial pos="-0.05317 0.104419 0.027454" quat="0.65058 0.529822 -0.0962034 0.535518" mass="3.5879" diaginertia="0.0349596 0.0281483 0.0106201"/>
              <joint name="joint4" pos="0 0 0" axis="0 0 1" range="-3.0718 -0.0698" damping="40"/>
              <body name="link5" pos="-0.0825 0.384 0" quat="0.707107 -0.707107 0 0">
                <inertial pos="-0.011953 0.041065 -0.038437" quat="0.987313 -0.0121954 0.0719187 -0.141037" mass="1.22595" diaginertia="0.0367625 0.0288531 0.00803437"/>
                <joint name="joint5" pos="0 0 0" axis="0 0 1" damping="2"/>
                <body name="link6" quat="0.707107 0.707107 0 0">
                  <inertial pos="0.060149 -0.014117 -0.010517" quat="0.101075 0.59332 0.0287227 0.798079" mass="1.66656" diaginertia="0.00584276 0.00431037 0.00159787"/>
                  <joint name="joint6" pos="0 0 0" axis="0 0 1" range="-0.0175 3.7525" damping="2"/>
                  <body name="link7" pos="0.088 0 0" quat="0.707107 0.707107 0 0">
                    <inertial pos="0.010517 -0.004252 0.061597" quat="0.992939 -0.0762041 0.0733595 -0.0537067" mass="0.735522" diaginertia="0.0127345 0.0101055 0.00451803"/>
                    <joint name="joint7" pos="0 0 0" axis="0 0 1" damping="2"/>
                    <body name="hand" pos="0 0 0.107" quat="0.92388 0 0 -0.382683">
                      <inertial pos="-0.01 0 0.03" mass="0.73" diaginertia="0.001 0.0025 0.0017"/>
                      <site name="gripper" pos="0 0 0.1"/>
                      <body name="left_finger" pos="0 0 0.0584">
                        <inertial pos="0 0 0" mass="0.015" diaginertia="2.375e-06 2.375e-06 7.5e-07"/>
                        <joint name="finger_joint1" class="finger" pos="0 0 0" axis="0 1 0" damping="10"/>
                      </body>
                      <body name="right_finger" pos="0 0 0.0584" quat="0 0 0 1">
                        <inertial pos="0 0 0" mass="0.015" diaginertia="2.375e-06 2.375e-06 7.5e-07"/>
                        <joint name="finger_joint2" class="finger" pos="0 0 0" axis="0 1 0" damping="10"/>
                      </body>
                    </body>
                  </body>
                </body>
              </body>
            </body>
          </body>
        </body>
      </body>
    </body>
    <body name="box" pos="0.5 0 0.03">
      <joint type="free" limited="false" actuatorfrclimited="false"/>
      <geom name="box" size="0.02 0.02 0.03" type="box" contype="2" friction="1 0.03 0.003" solref="0.01" rgba="0 1 0 1"/>
    </body>
    <body name="mocap_target" mocap="true">
      <geom size="0.02 0.02 0.03" type="box" contype="0" conaffinity="0" rgba="1 0 0 0.2"/>
    </body>
  </worldbody>

  <equality>
    <joint joint1="finger_joint1" joint2="finger_joint2" polycoef="0 1 0 0 0" solref="0.005" solimp="0.95 0.99"/>
  </equality>

  <actuator>
    <general name="actuator1" class="panda" joint="joint1" gainprm="1000" biasprm="0 -1000 -20"/>
    <general name="actuator2" class="panda" joint="joint2" ctrlrange="-1.7628 1.7628" gainprm="1000" biasprm="0 -1000 -20"/>
    <general name="actuator3" class="panda" joint="joint3" gainprm="750" biasprm="0 -750 -4"/>
    <general name="actuator4" class="panda" joint="joint4" ctrlrange="-3.0718 -0.0698" gainprm="750" biasprm="0 -750 -4"/>
    <general name="actuator5" class="panda" joint="joint5" forcerange="-12 12" gainprm="300" biasprm="0 -300 -2"/>
    <general name="actuator6" class="panda" joint="joint6" ctrlrange="-0.0175 3.7525" forcerange="-12 12" gainprm="300" biasprm="0 -300 -2"/>
    <general name="actuator7" class="panda" joint="joint7" forcerange="-12 12" gainprm="300" biasprm="0 -300 -2"/>
    <general name="actuator8" class="panda" joint="finger_joint1" ctrlrange="0 0.04" forcerange="-200 200" gainprm="350" biasprm="0 -350 -10"/>
  </actuator>

  <keyframe>
    <key name="home" qpos="0 0.3 0 -1.57079 0 2 -0.7853 0.04 0.04 0.7 0 0.03 1 0 0 0" ctrl="0 0.3 0 -1.57079 0 2 -0.7853 0.04"/>
    <key name="pickup" qpos="0.2897 0.50732 -0.140016 -2.176 -0.0310497 2.51592 -0.49251 0.04 0.0399982 0.511684 0.0645413 0.0298665 0.665781 0 0 -0.746147" ctrl="0.2897 0.423 -0.144392 -2.13105 -0.0291743 2.52586 -0.492492 0.04"/>
    <key name="pickup1" qpos="0.2897 0.496673 -0.142836 -2.14746 -0.0295746 2.52378 -0.492496 0.04 0.0399988 0.529553 0.0731702 0.0299388 0.94209 8.84613e-06 -4.97524e-06 -0.335361" ctrl="0.2897 0.458 -0.144392 -2.13105 -0.0291743 2.52586 -0.492492 0.04"/>
  </keyframe>
</mujoco>
